Workbook

Sheet Pokemon
A1: # | B1: Name | C1: Type | D1: Quantidades | E1: Region | F1: Classificação | G1: Total | H1: HP | I1: Attack | J1: Defense | K1: Special Attack | L1: Special Defense | M1: Speed | N1: Média dos attacks | O1: Código Pokemon
A2: 1 | B2: Bulbasaur | C2: GRASS | D2: =COUNTIF($C$2:$C$1168,Tabela1[[#This Row],[Type]]) -> 93 | E2: =IF(A2<=151,"Kanto",IF(A2<=251,"Johto",IF(A2<=386,"Hoenn",IF(A2<=493,"Sinnoh",IF(A2<=649,"Unova",IF(A2<=721,"Kalos",IF(A2<=809,"Alola",IF(A2<=905,"Galar","Paldea")))))))) -> Kanto | F2: =IF(G2>=600,"Lendário",IF(G2>=500,"Forte","Normal")) -> Normal | G2: 318 | H2: 45 | I2: 49 | J2: 49 | K2: 65 | L2: 65 | M2: 45 | N2: =AVERAGE($I$2:$I$1168) -> 78.907455 | O2: =CONCATENATE(A2,"-",B2) -> 1-Bulbasaur
A3: 1 | B3: =B2 -> Bulbasaur | C3: POISON | D3: =COUNTIF($C$2:$C$1168,Tabela1[[#This Row],[Type]]) -> 61 | E3: =IF(A3<=151,"Kanto",IF(A3<=251,"Johto",IF(A3<=386,"Hoenn",IF(A3<=493,"Sinnoh",IF(A3<=649,"Unova",IF(A3<=721,"Kalos",IF(A3<=809,"Alola",IF(A3<=905,"Galar","Paldea")))))))) -> Kanto | F3: =IF(G3>=600,"Lendário",IF(G3>=500,"Forte","Normal")) -> Normal | G3: =G2 -> 318 | H3: =H2 -> 45 | I3: =I2 -> 49 | J3: =J2 -> 49 | K3: =K2 -> 65 | L3: =L2 -> 65 | M3: =M2 -> 45 | N3: =AVERAGE($I$2:$I$1168) -> 78.907455 | O3: =CONCATENATE(A3,"-",B3) -> 1-Bulbasaur
A4: 2 | B4: Ivysaur | C4: GRASS | D4: =COUNTIF($C$2:$C$1168,Tabela1[[#This Row],[Type]]) -> 93 | E4: =IF(A4<=151,"Kanto",IF(A4<=251,"Johto",IF(A4<=386,"Hoenn",IF(A4<=493,"Sinnoh",IF(A4<=649,"Unova",IF(A4<=721,"Kalos",IF(A4<=809,"Alola",IF(A4<=905,"Galar","Paldea")))))))) -> Kanto | F4: =IF(G4>=600,"Lendário",IF(G4>=500,"Forte","Normal")) -> Normal | G4: 405 | H4: 60 | I4: 62 | J4: 63 | K4: 80 | L4: 80 | M4: 60 | N4: =AVERAGE($I$2:$I$1168) -> 78.907455 | O4: =CONCATENATE(A4,"-",B4) -> 2-Ivysaur
A5: 2 | B5: =B4 -> Ivysaur | C5: POISON | D5: =COUNTIF($C$2:$C$1168,Tabela1[[#This Row],[Type]]) -> 61 | E5: =IF(A5<=151,"Kanto",IF(A5<=251,"Johto",IF(A5<=386,"Hoenn",IF(A5<=493,"Sinnoh",IF(A5<=649,"Unova",IF(A5<=721,"Kalos",IF(A5<=809,"Alola",IF(A5<=905,"Galar","Paldea")))))))) -> Kanto | F5: =IF(G5>=600,"Lendário",IF(G5>=500,"Forte","Normal")) -> Normal | G5: =G4 -> 405 | H5: =H4 -> 60 | I5: =I4 -> 62 | J5: =J4 -> 63 | K5: =K4 -> 80 | L5: =L4 -> 80 | M5: =M4 -> 60 | N5: =AVERAGE($I$2:$I$1168) -> 78.907455 | O5: =CONCATENATE(A5,"-",B5) -> 2-Ivysaur
A6: 3 | B6: Venusaur | C6: GRASS | D6: =COUNTIF($C$2:$C$1168,Tabela1[[#This Row],[Type]]) -> 93 | E6: =IF(A6<=151,"Kanto",IF(A6<=251,"Johto",IF(A6<=386,"Hoenn",IF(A6<=493,"Sinnoh",IF(A6<=649,"Unova",IF(A6<=721,"Kalos",IF(A6<=809,"Alola",IF(A6<=905,"Galar","Paldea")))))))) -> Kanto | F6: =IF(G6>=600,"Lendário",IF(G6>=500,"Forte","Normal")) -> Forte | G6: 525 | H6: 80 | I6: 82 | J6: 83 | K6: 100 | L6: 100 | M6: 80 | N6: =AVERAGE($I$2:$I$1168) -> 78.907455 | O6: =CONCATENATE(A6,"-",B6) -> 3-Venusaur
A7: 3 | B7: =B6 -> Venusaur | C7: POISON | D7: =COUNTIF($C$2:$C$1168,Tabela1[[#This Row],[Type]]) -> 61 | E7: =IF(A7<=151,"Kanto",IF(A7<=251,"Johto",IF(A7<=386,"Hoenn",IF(A7<=493,"Sinnoh",IF(A7<=649,"Unova",IF(A7<=721,"Kalos",IF(A7<=809,"Alola",IF(A7<=905,"Galar","Paldea")))))))) -> Kanto | F7: =IF(G7>=600,"Lendário",IF(G7>=500,"Forte","Normal")) -> Forte | G7: =G6 -> 525 | H7: =H6 -> 80 | I7: =I6 -> 82 | J7: =J6 -> 83 | K7: =K6 -> 100 | L7: =L6 -> 100 | M7: =M6 -> 80 | N7: =AVERAGE($I$2:$I$1168) -> 78.907455 | O7: =CONCATENATE(A7,"-",B7) -> 3-Venusaur
A8: 3.1 | B8: Mega Venusaur | C8: GRASS | D8: =COUNTIF($C$2:$C$1168,Tabela1[[#This Row],[Type]]) -> 93 | E8: =IF(A8<=151,"Kanto",IF(A8<=251,"Johto",IF(A8<=386,"Hoenn",IF(A8<=493,"Sinnoh",IF(A8<=649,"Unova",IF(A8<=721,"Kalos",IF(A8<=809,"Alola",IF(A8<=905,"Galar","Paldea")))))))) -> Kanto | F8: =IF(G8>=600,"Lendário",IF(G8>=500,"Forte","Normal")) -> Lendário | G8: 625 | H8: 80 | I8: 100 | J8: 123 | K8: 122 | L8: 120 | M8: 80 | N8: =AVERAGE($I$2:$I$1168) -> 78.907455 | O8: =CONCATENATE(A8,"-",B8) -> 3,1-Mega Venusaur
A9: 3.1 | B9: Mega Venusaur | C9: POISON | D9: =COUNTIF($C$2:$C$1168,Tabela1[[#This Row],[Type]]) -> 61 | E9: =IF(A9<=151,"Kanto",IF(A9<=251,"Johto",IF(A9<=386,"Hoenn",IF(A9<=493,"Sinnoh",IF(A9<=649,"Unova",IF(A9<=721,"Kalos",IF(A9<=809,"Alola",IF(A9<=905,"Galar","Paldea")))))))) -> Kanto | F9: =IF(G9>=600,"Lendário",IF(G9>=500,"Forte","Normal")) -> Lendário | G9: =G8 -> 625 | H9: =H8 -> 80 | I9: =I8 -> 100 | J9: =J8 -> 123 | K9: =K8 -> 122 | L9: =L8 -> 120 | M9: =M8 -> 80 | N9: =AVERAGE($I$2:$I$1168) -> 78.907455 | O9: =CONCATENATE(A9,"-",B9) -> 3,1-Mega Venusaur
A10: 4 | B10: Charmander | C10: FIRE | D10: =COUNTIF($C$2:$C$1168,Tabela1[[#This Row],[Type]]) -> 62 | E10: =IF(A10<=151,"Kanto",IF(A10<=251,"Johto",IF(A10<=386,"Hoenn",IF(A10<=493,"Sinnoh",IF(A10<=649,"Unova",IF(A10<=721,"Kalos",IF(A10<=809,"Alola",IF(A10<=905,"Galar","Paldea")))))))) -> Kanto | F10: =IF(G10>=600,"Lendário",IF(G10>=500,"Forte","Normal")) -> Normal | G10: 309 | H10: 39 | I10: 52 | J10: 43 | K10: 60 | L10: 50 | M10: 65 | N10: =AVERAGE($I$2:$I$1168) -> 78.907455 | O10: =CONCATENATE(A10,"-",B10) -> 4-Charmander
A11: 5 | B11: Charmeleon | C11: FIRE | D11: =COUNTIF($C$2:$C$1168,Tabela1[[#This Row],[Type]]) -> 62 | E11: =IF(A11<=151,"Kanto",IF(A11<=251,"Johto",IF(A11<=386,"Hoenn",IF(A11<=493,"Sinnoh",IF(A11<=649,"Unova",IF(A11<=721,"Kalos",IF(A11<=809,"Alola",IF(A11<=905,"Galar","Paldea")))))))) -> Kanto | F11: =IF(G11>=600,"Lendário",IF(G11>=500,"Forte","Normal")) -> Normal | G11: 405 | H11: 58 | I11: 64 | J11: 58 | K11: 80 | L11: 65 | M11: 80 | N11: =AVERAGE($I$2:$I$1168) -> 78.907455 | O11: =CONCATENATE(A11,"-",B11) -> 5-Charmeleon
A12: 6 | B12: Charizard | C12: FIRE | D12: =COUNTIF($C$2:$C$1168,Tabela1[[#This Row],[Type]]) -> 62 | E12: =IF(A12<=151,"Kanto",IF(A12<=251,"Johto",IF(A12<=386,"Hoenn",IF(A12<=493,"Sinnoh",IF(A12<=649,"Unova",IF(A12<=721,"Kalos",IF(A12<=809,"Alola",IF(A12<=905,"Galar","Paldea")))))))) -> Kanto | F12: =IF(G12>=600,"Lendário",IF(G12>=500,"Forte","Normal")) -> Forte | G12: 534 | H12: 78 | I12: 84 | J12: 78 | K12: 109 | L12: 85 | M12: 100 | N12: =AVERAGE($I$2:$I$1168) -> 78.907455 | O12: =CONCATENATE(A12,"-",B12) -> 6-Charizard
A13: 6 | B13: =B12 -> Charizard | C13: FLYING | D13: =COUNTIF($C$2:$C$1168,Tabela1[[#This Row],[Type]]) -> 100 | E13: =IF(A13<=151,"Kanto",IF(A13<=251,"Johto",IF(A13<=386,"Hoenn",IF(A13<=493,"Sinnoh",IF(A13<=649,"Unova",IF(A13<=721,"Kalos",IF(A13<=809,"Alola",IF(A13<=905,"Galar","Paldea")))))))) -> Kanto | F13: =IF(G13>=600,"Lendário",IF(G13>=500,"Forte","Normal")) -> Forte | G13: =G12 -> 534 | H13: =H12 -> 78 | I13: =I12 -> 84 | J13: =J12 -> 78 | K13: =K12 -> 109 | L13: =L12 -> 85 | M13: =M12 -> 100 | N13: =AVERAGE($I$2:$I$1168) -> 78.907455 | O13: =CONCATENATE(A13,"-",B13) -> 6-Charizard
A14: 6.1 | B14: Mega Charizard X | C14: FIRE | D14: =COUNTIF($C$2:$C$1168,Tabela1[[#This Row],[Type]]) -> 62 | E14: =IF(A14<=151,"Kanto",IF(A14<=251,"Johto",IF(A14<=386,"Hoenn",IF(A14<=493,"Sinnoh",IF(A14<=649,"Unova",IF(A14<=721,"Kalos",IF(A14<=809,"Alola",IF(A14<=905,"Galar","Paldea")))))))) -> Kanto | F14: =IF(G14>=600,"Lendário",IF(G14>=500,"Forte","Normal")) -> Lendário | G14: 634 | H14: 78 | I14: 130 | J14: 111 | K14: 130 | L14: 85 | M14: 100 | N14: =AVERAGE($I$2:$I$1168) -> 78.907455 | O14: =CONCATENATE(A14,"-",B14) -> 6,1-Mega Charizard X
A15: 6.1 | B15: Mega Charizard X | C15: DRAGON | D15: =COUNTIF($C$2:$C$1168,Tabela1[[#This Row],[Type]]) -> 44 | E15: =IF(A15<=151,"Kanto",IF(A15<=251,"Johto",IF(A15<=386,"Hoenn",IF(A15<=493,"Sinnoh",IF(A15<=649,"Unova",IF(A15<=721,"Kalos",IF(A15<=809,"Alola",IF(A15<=905,"Galar","Paldea")))))))) -> Kanto | F15: =IF(G15>=600,"Lendário",IF(G15>=500,"Forte","Normal")) -> Lendário | G15: =G14 -> 634 | H15: =H14 -> 78 | I15: =I14 -> 130 | J15: =J14 -> 111 | K15: =K14 -> 130 | L15: =L14 -> 85 | M15: =M14 -> 100 | N15: =AVERAGE($I$2:$I$1168) -> 78.907455 | O15: =CONCATENATE(A15,"-",B15) -> 6,1-Mega Charizard X
A16: 6.2 | B16: Mega Charizard Y | C16: FIRE | D16: =COUNTIF($C$2:$C$1168,Tabela1[[#This Row],[Type]]) -> 62 | E16: =IF(A16<=151,"Kanto",IF(A16<=251,"Johto",IF(A16<=386,"Hoenn",IF(A16<=493,"Sinnoh",IF(A16<=649,"Unova",IF(A16<=721,"Kalos",IF(A16<=809,"Alola",IF(A16<=905,"Galar","Paldea")))))))) -> Kanto | F16: =IF(G16>=600,"Lendário",IF(G16>=500,"Forte","Normal")) -> Lendário | G16: 634 | H16: 78 | I16: 104 | J16: 78 | K16: 159 | L16: 115 | M16: 100 | N16: =AVERAGE($I$2:$I$1168) -> 78.907455 | O16: =CONCATENATE(A16,"-",B16) -> 6,2-Mega Charizard Y
A17: 6.2 | B17: Mega Charizard Y | C17: FLYING | D17: =COUNTIF($C$2:$C$1168,Tabela1[[#This Row],[Type]]) -> 100 | E17: =IF(A17<=151,"Kanto",IF(A17<=251,"Johto",IF(A17<=386,"Hoenn",IF(A17<=493,"Sinnoh",IF(A17<=649,"Unova",IF(A17<=721,"Kalos",IF(A17<=809,"Alola",IF(A17<=905,"Galar","Paldea")))))))) -> Kanto | F17: =IF(G17>=600,"Lendário",IF(G17>=500,"Forte","Normal")) -> Lendário | G17: =G16 -> 634 | H17: =H16 -> 78 | I17: =I16 -> 104 | J17: =J16 -> 78 | K17: =K16 -> 159 | L17: =L16 -> 115 | M17: =M16 -> 100 | N17: =AVERAGE($I$2:$I$1168) -> 78.907455 | O17: =CONCATENATE(A17,"-",B17) -> 6,2-Mega Charizard Y
A18: 7 | B18: Squirtle | C18: WATER | D18: =COUNTIF($C$2:$C$1168,Tabela1[[#This Row],[Type]]) -> 121 | E18: =IF(A18<=151,"Kanto",IF(A18<=251,"Johto",IF(A18<=386,"Hoenn",IF(A18<=493,"Sinnoh",IF(A18<=649,"Unova",IF(A18<=721,"Kalos",IF(A18<=809,"Alola",IF(A18<=905,"Galar","Paldea")))))))) -> Kanto | F18: =IF(G18>=600,"Lendário",IF(G18>=500,"Forte","Normal")) -> Normal | G18: 314 | H18: 44 | I18: 48 | J18: 65 | K18: 50 | L18: 64 | M18: 43 | N18: =AVERAGE($I$2:$I$1168) -> 78.907455 | O18: =CONCATENATE(A18,"-",B18) -> 7-Squirtle
A19: 8 | B19: Wartortle | C19: WATER | D19: =COUNTIF($C$2:$C$1168,Tabela1[[#This Row],[Type]]) -> 121 | E19: =IF(A19<=151,"Kanto",IF(A19<=251,"Johto",IF(A19<=386,"Hoenn",IF(A19<=493,"Sinnoh",IF(A19<=649,"Unova",IF(A19<=721,"Kalos",IF(A19<=809,"Alola",IF(A19<=905,"Galar","Paldea")))))))) -> Kanto | F19: =IF(G19>=600,"Lendário",IF(G19>=500,"Forte","Normal")) -> Normal | G19: 405 | H19: 59 | I19: 63 | J19: 80 | K19: 65 | L19: 80 | M19: 58 | N19: =AVERAGE($I$2:$I$1168) -> 78.907455 | O19: =CONCATENATE(A19,"-",B19) -> 8-Wartortle
A20: 9 | B20: Blastoise | C20: WATER | D20: =COUNTIF($C$2:$C$1168,Tabela1[[#This Row],[Type]]) -> 121 | E20: =IF(A20<=151,"Kanto",IF(A20<=251,"Johto",IF(A20<=386,"Hoenn",IF(A20<=493,"Sinnoh",IF(A20<=649,"Unova",IF(A20<=721,"Kalos",IF(A20<=809,"Alola",IF(A20<=905,"Galar","Paldea")))))))) -> Kanto | F20: =IF(G20>=600,"Lendário",IF(G20>=500,"Forte","Normal")) -> Forte | G20: 530 | H20: 79 | I20: 83 | J20: 100 | K20: 85 | L20: 105 | M20: 78 | N20: =AVERAGE($I$2:$I$1168) -> 78.907455 | O20: =CONCATENATE(A20,"-",B20) -> 9-Blastoise
A21: 9.1 | B21: Mega Blastoise | C21: WATER | D21: =COUNTIF($C$2:$C$1168,Tabela1[[#This Row],[Type]]) -> 121 | E21: =IF(A21<=151,"Kanto",IF(A21<=251,"Johto",IF(A21<=386,"Hoenn",IF(A21<=493,"Sinnoh",IF(A21<=649,"Unova",IF(A21<=721,"Kalos",IF(A21<=809,"Alola",IF(A21<=905,"Galar","Paldea")))))))) -> Kanto | F21: =IF(G21>=600,"Lendário",IF(G21>=500,"Forte","Normal")) -> Lendário | G21: 630 | H21: 79 | I21: 103 | J21: 120 | K21: 135 | L21: 115 | M21: 78 | N21: =AVERAGE($I$2:$I$1168) -> 78.907455 | O21: =CONCATENATE(A21,"-",B21) -> 9,1-Mega Blastoise
A22: 10 | B22: Caterpie | C22: BUG | D22: =COUNTIF($C$2:$C$1168,Tabela1[[#This Row],[Type]]) -> 71 | E22: =IF(A22<=151,"Kanto",IF(A22<=251,"Johto",IF(A22<=386,"Hoenn",IF(A22<=493,"Sinnoh",IF(A22<=649,"Unova",IF(A22<=721,"Kalos",IF(A22<=809,"Alola",IF(A22<=905,"Galar","Paldea")))))))) -> Kanto | F22: =IF(G22>=600,"Lendário",IF(G22>=500,"Forte","Normal")) -> Normal | G22: 195 | H22: 45 | I22: 30 | J22: 35 | K22: 20 | L22: 20 | M22: 45 | N22: =AVERAGE($I$2:$I$1168) -> 78.907455 | O22: =CONCATENATE(A22,"-",B22) -> 10-Caterpie
A23: 11 | B23: Metapod | C23: BUG | D23: =COUNTIF($C$2:$C$1168,Tabela1[[#This Row],[Type]]) -> 71 | E23: =IF(A23<=151,"Kanto",IF(A23<=251,"Johto",IF(A23<=386,"Hoenn",IF(A23<=493,"Sinnoh",IF(A23<=649,"Unova",IF(A23<=721,"Kalos",IF(A23<=809,"Alola",IF(A23<=905,"Galar","Paldea")))))))) -> Kanto | F23: =IF(G23>=600,"Lendário",IF(G23>=500,"Forte","Normal")) -> Normal | G23: 205 | H23: 50 | I23: 20 | J23: 55 | K23: 25 | L23: 25 | M23: 30 | N23: =AVERAGE($I$2:$I$1168) -> 78.907455 | O23: =CONCATENATE(A23,"-",B23) -> 11-Metapod
A24: 12 | B24: Butterfree | C24: BUG | D24: =COUNTIF($C$2:$C$1168,Tabela1[[#This Row],[Type]]) -> 71 | E24: =IF(A24<=151,"Kanto",IF(A24<=251,"Johto",IF(A24<=386,"Hoenn",IF(A24<=493,"Sinnoh",IF(A24<=649,"Unova",IF(A24<=721,"Kalos",IF(A24<=809,"Alola",IF(A24<=905,"Galar","Paldea")))))))) -> Kanto | F24: =IF(G24>=600,"Lendário",IF(G24>=500,"Forte","Normal")) -> Normal | G24: 385 | H24: 60 | I24: 45 | J24: 50 | K24: 80 | L24: 80 | M24: 70 | N24: =AVERAGE($I$2:$I$1168) -> 78.907455 | O24: =CONCATENATE(A24,"-",B24) -> 12-Butterfree
A25: 12 | B25: =B24 -> Butterfree | C25: FLYING | D25: =COUNTIF($C$2:$C$1168,Tabela1[[#This Row],[Type]]) -> 100 | E25: =IF(A25<=151,"Kanto",IF(A25<=251,"Johto",IF(A25<=386,"Hoenn",IF(A25<=493,"Sinnoh",IF(A25<=649,"Unova",IF(A25<=721,"Kalos",IF(A25<=809,"Alola",IF(A25<=905,"Galar","Paldea")))))))) -> Kanto | F25: =IF(G25>=600,"Lendário",IF(G25>=500,"Forte","Normal")) -> Normal | G25: =G24 -> 385 | H25: =H24 -> 60 | I25: =I24 -> 45 | J25: =J24 -> 50 | K25: =K24 -> 80 | L25: =L24 -> 80 | M25: =M24 -> 70 | N25: =AVERAGE($I$2:$I$1168) -> 78.907455 | O25: =CONCATENATE(A25,"-",B25) -> 12-Butterfree
A26: 13 | B26: Weedle | C26: BUG | D26: =COUNTIF($C$2:$C$1168,Tabela1[[#This Row],[Type]]) -> 71 | E26: =IF(A26<=151,"Kanto",IF(A26<=251,"Johto",IF(A26<=386,"Hoenn",IF(A26<=493,"Sinnoh",IF(A26<=649,"Unova",IF(A26<=721,"Kalos",IF(A26<=809,"Alola",IF(A26<=905,"Galar","Paldea")))))))) -> Kanto | F26: =IF(G26>=600,"Lendário",IF(G26>=500,"Forte","Normal")) -> Normal | G26: 195 | H26: 40 | I26: 35 | J26: 30 | K26: 20 | L26: 20 | M26: 50 | N26: =AVERAGE($I$2:$I$1168) -> 78.907455 | O26: =CONCATENATE(A26,"-",B26) -> 13-Weedle
A27: 13 | B27: =B26 -> Weedle | C27: POISON | D27: =COUNTIF($C$2:$C$1168,Tabela1[[#This Row],[Type]]) -> 61 | E27: =IF(A27<=151,"Kanto",IF(A27<=251,"Johto",IF(A27<=386,"Hoenn",IF(A27<=493,"Sinnoh",IF(A27<=649,"Unova",IF(A27<=721,"Kalos",IF(A27<=809,"Alola",IF(A27<=905,"Galar","Paldea")))))))) -> Kanto | F27: =IF(G27>=600,"Lendário",IF(G27>=500,"Forte","Normal")) -> Normal | G27: =G26 -> 195 | H27: =H26 -> 40 | I27: =I26 -> 35 | J27: =J26 -> 30 | K27: =K26 -> 20 | L27: =L26 -> 20 | M27: =M26 -> 50 | N27: =AVERAGE($I$2:$I$1168) -> 78.907455 | O27: =CONCATENATE(A27,"-",B27) -> 13-Weedle
A28: 14 | B28: Kakuna | C28: BUG | D28: =COUNTIF($C$2:$C$1168,Tabela1[[#This Row],[Type]]) -> 71 | E28: =IF(A28<=151,"Kanto",IF(A28<=251,"Johto",IF(A28<=386,"Hoenn",IF(A28<=493,"Sinnoh",IF(A28<=649,"Unova",IF(A28<=721,"Kalos",IF(A28<=809,"Alola",IF(A28<=905,"Galar","Paldea")))))))) -> Kanto | F28: =IF(G28>=600,"Lendário",IF(G28>=500,"Forte","Normal")) -> Normal | G28: 205 | H28: 45 | I28: 25 | J28: 50 | K28: 25 | L28: 25 | M28: 35 | N28: =AVERAGE($I$2:$I$1168) -> 78.907455 | O28: =CONCATENATE(A28,"-",B28) -> 14-Kakuna
A29: 14 | B29: =B28 -> Kakuna | C29: POISON | D29: =COUNTIF($C$2:$C$1168,Tabela1[[#This Row],[Type]]) -> 61 | E29: =IF(A29<=151,"Kanto",IF(A29<=251,"Johto",IF(A29<=386,"Hoenn",IF(A29<=493,"Sinnoh",IF(A29<=649,"Unova",IF(A29<=721,"Kalos",IF(A29<=809,"Alola",IF(A29<=905,"Galar","Paldea")))))))) -> Kanto | F29: =IF(G29>=600,"Lendário",IF(G29>=500,"Forte","Normal")) -> Normal | G29: =G28 -> 205 | H29: =H28 -> 45 | I29: =I28 -> 25 | J29: =J28 -> 50 | K29: =K28 -> 25 | L29: =L28 -> 25 | M29: =M28 -> 35 | N29: =AVERAGE($I$2:$I$1168) -> 78.907455 | O29: =CONCATENATE(A29,"-",B29) -> 14-Kakuna
A30: 15 | B30: Beedrill | C30: BUG | D30: =COUNTIF($C$2:$C$1168,Tabela1[[#This Row],[Type]]) -> 71 | E30: =IF(A30<=151,"Kanto",IF(A30<=251,"Johto",IF(A30<=386,"Hoenn",IF(A30<=493,"Sinnoh",IF(A30<=649,"Unova",IF(A30<=721,"Kalos",IF(A30<=809,"Alola",IF(A30<=905,"Galar","Paldea")))))))) -> Kanto | F30: =IF(G30>=600,"Lendário",IF(G30>=500,"Forte","Normal")) -> Normal | G30: 385 | H30: 65 | I30: 80 | J30: 40 | K30: 45 | L30: 80 | M30: 75 | N30: =AVERAGE($I$2:$I$1168) -> 78.907455 | O30: =CONCATENATE(A30,"-",B30) -> 15-Beedrill
A31: 15 | B31: =B30 -> Beedrill | C31: POISON | D31: =COUNTIF($C$2:$C$1168,Tabela1[[#This Row],[Type]]) -> 61 | E31: =IF(A31<=151,"Kanto",IF(A31<=251,"Johto",IF(A31<=386,"Hoenn",IF(A31<=493,"Sinnoh",IF(A31<=649,"Unova",IF(A31<=721,"Kalos",IF(A31<=809,"Alola",IF(A31<=905,"Galar","Paldea")))))))) -> Kanto | F31: =IF(G31>=600,"Lendário",IF(G31>=500,"Forte","Normal")) -> Normal | G31: =G30 -> 385 | H31: =H30 -> 65 | I31: =I30 -> 80 | J31: =J30 -> 40 | K31: =K30 -> 45 | L31: =L30 -> 80 | M31: =M30 -> 75 | N31: =AVERAGE($I$2:$I$1168) -> 78.907455 | O31: =CONCATENATE(A31,"-",B31) -> 15-Beedrill
A32: 16 | B32: Pidgey | C32: NORMAL | D32: =COUNTIF($C$2:$C$1168,Tabela1[[#This Row],[Type]]) -> 99 | E32: =IF(A32<=151,"Kanto",IF(A32<=251,"Johto",IF(A32<=386,"Hoenn",IF(A32<=493,"Sinnoh",IF(A32<=649,"Unova",IF(A32<=721,"Kalos",IF(A32<=809,"Alola",IF(A32<=905,"Galar","Paldea")))))))) -> Kanto | F32: =IF(G32>=600,"Lendário",IF(G32>=500,"Forte","Normal")) -> Normal | G32: 251 | H32: 40 | I32: 45 | J32: 40 | K32: 35 | L32: 35 | M32: 56 | N32: =AVERAGE($I$2:$I$1168) -> 78.907455 | O32: =CONCATENATE(A32,"-",B32) -> 16-Pidgey
A33: 17 | B33: Pidgeotto | C33: NORMAL | D33: =COUNTIF($C$2:$C$1168,Tabela1[[#This Row],[Type]]) -> 99 | E33: =IF(A33<=151,"Kanto",IF(A33<=251,"Johto",IF(A33<=386,"Hoenn",IF(A33<=493,"Sinnoh",IF(A33<=649,"Unova",IF(A33<=721,"Kalos",IF(A33<=809,"Alola",IF(A33<=905,"Galar","Paldea")))))))) -> Kanto | F33: =IF(G33>=600,"Lendário",IF(G33>=500,"Forte","Normal")) -> Normal | G33: 349 | H33: 63 | I33: 60 | J33: 55 | K33: 50 | L33: 50 | M33: 71 | N33: =AVERAGE($I$2:$I$1168) -> 78.907455 | O33: =CONCATENATE(A33,"-",B33) -> 17-Pidgeotto
A34: 18 | B34: Pidgeot | C34: NORMAL | D34: =COUNTIF($C$2:$C$1168,Tabela1[[#This Row],[Type]]) -> 99 | E34: =IF(A34<=151,"Kanto",IF(A34<=251,"Johto",IF(A34<=386,"Hoenn",IF(A34<=493,"Sinnoh",IF(A34<=649,"Unova",IF(A34<=721,"Kalos",IF(A34<=809,"Alola",IF(A34<=905,"Galar","Paldea")))))))) -> Kanto | F34: =IF(G34>=600,"Lendário",IF(G34>=500,"Forte","Normal")) -> Normal | G34: 469 | H34: 83 | I34: 80 | J34: 75 | K34: 70 | L34: 70 | M34: 91 | N34: =AVERAGE($I$2:$I$1168) -> 78.907455 | O34: =CONCATENATE(A34,"-",B34) -> 18-Pidgeot
A35: 19 | B35: Rattata | C35: NORMAL | D35: =COUNTIF($C$2:$C$1168,Tabela1[[#This Row],[Type]]) -> 99 | E35: =IF(A35<=151,"Kanto",IF(A35<=251,"Johto",IF(A35<=386,"Hoenn",IF(A35<=493,"Sinnoh",IF(A35<=649,"Unova",IF(A35<=721,"Kalos",IF(A35<=809,"Alola",IF(A35<=905,"Galar","Paldea")))))))) -> Kanto | F35: =IF(G35>=600,"Lendário",IF(G35>=500,"Forte","Normal")) -> Normal | G35: 253 | H35: 30 | I35: 56 | J35: 35 | K35: 25 | L35: 35 | M35: 72 | N35: =AVERAGE($I$2:$I$1168) -> 78.907455 | O35: =CONCATENATE(A35,"-",B35) -> 19-Rattata
A36: 19 | B36: =B35 -> Rattata | C36: FLYING | D36: =COUNTIF($C$2:$C$1168,Tabela1[[#This Row],[Type]]) -> 100 | E36: =IF(A36<=151,"Kanto",IF(A36<=251,"Johto",IF(A36<=386,"Hoenn",IF(A36<=493,"Sinnoh",IF(A36<=649,"Unova",IF(A36<=721,"Kalos",IF(A36<=809,"Alola",IF(A36<=905,"Galar","Paldea")))))))) -> Kanto | F36: =IF(G36>=600,"Lendário",IF(G36>=500,"Forte","Normal")) -> Normal | G36: =G35 -> 253 | H36: =H35 -> 30 | I36: =I35 -> 56 | J36: =J35 -> 35 | K36: =K35 -> 25 | L36: =L35 -> 35 | M36: =M35 -> 72 | N36: =AVERAGE($I$2:$I$1168) -> 78.907455 | O36: =CONCATENATE(A36,"-",B36) -> 19-Rattata
A37: 20 | B37: Raticate | C37: NORMAL | D37: =COUNTIF($C$2:$C$1168,Tabela1[[#This Row],[Type]]) -> 99 | E37: =IF(A37<=151,"Kanto",IF(A37<=251,"Johto",IF(A37<=386,"Hoenn",IF(A37<=493,"Sinnoh",IF(A37<=649,"Unova",IF(A37<=721,"Kalos",IF(A37<=809,"Alola",IF(A37<=905,"Galar","Paldea")))))))) -> Kanto | F37: =IF(G37>=600,"Lendário",IF(G37>=500,"Forte","Normal")) -> Normal | G37: 413 | H37: 55 | I37: 81 | J37: 60 | K37: 50 | L37: 70 | M37: 97 | N37: =AVERAGE($I$2:$I$1168) -> 78.907455 | O37: =CONCATENATE(A37,"-",B37) -> 20-Raticate
A38: 21 | B38: Spearow | C38: NORMAL | D38: =COUNTIF($C$2:$C$1168,Tabela1[[#This Row],[Type]]) -> 99 | E38: =IF(A38<=151,"Kanto",IF(A38<=251,"Johto",IF(A38<=386,"Hoenn",IF(A38<=493,"Sinnoh",IF(A38<=649,"Unova",IF(A38<=721,"Kalos",IF(A38<=809,"Alola",IF(A38<=905,"Galar","Paldea")))))))) -> Kanto | F38: =IF(G38>=600,"Lendário",IF(G38>=500,"Forte","Normal")) -> Normal | G38: 262 | H38: 40 | I38: 60 | J38: 30 | K38: 31 | L38: 31 | M38: 70 | N38: =AVERAGE($I$2:$I$1168) -> 78.907455 | O38: =CONCATENATE(A38,"-",B38) -> 21-Spearow
A39: 22 | B39: Fearow | C39: NORMAL | D39: =COUNTIF($C$2:$C$1168,Tabela1[[#This Row],[Type]]) -> 99 | E39: =IF(A39<=151,"Kanto",IF(A39<=251,"Johto",IF(A39<=386,"Hoenn",IF(A39<=493,"Sinnoh",IF(A39<=649,"Unova",IF(A39<=721,"Kalos",IF(A39<=809,"Alola",IF(A39<=905,"Galar","Paldea")))))))) -> Kanto | F39: =IF(G39>=600,"Lendário",IF(G39>=500,"Forte","Normal")) -> Normal | G39: 442 | H39: 65 | I39: 90 | J39: 65 | K39: 61 | L39: 61 | M39: 100 | N39: =AVERAGE($I$2:$I$1168) -> 78.907455 | O39: =CONCATENATE(A39,"-",B39) -> 22-Fearow
A40: 23 | B40: Ekans | C40: POISON | D40: =COUNTIF($C$2:$C$1168,Tabela1[[#This Row],[Type]]) -> 61 | E40: =IF(A40<=151,"Kanto",IF(A40<=251,"Johto",IF(A40<=386,"Hoenn",IF(A40<=493,"Sinnoh",IF(A40<=649,"Unova",IF(A40<=721,"Kalos",IF(A40<=809,"Alola",IF(A40<=905,"Galar","Paldea")))))))) -> Kanto | F40: =IF(G40>=600,"Lendário",IF(G40>=500,"Forte","Normal")) -> Normal | G40: 288 | H40: 35 | I40: 60 | J40: 44 | K40: 40 | L40: 54 | M40: 55 | N40: =AVERAGE($I$2:$I$1168) -> 78.907455 | O40: =CONCATENATE(A40,"-",B40) -> 23-Ekans
...

Sheet Consulta Pokemon
A1: 🔎 POKÉDEX INTERATIVA
A3: Pokemom: | B3: Bulbasaur
A4: Região: | B4: =_xlfn.XLOOKUP(B3,Pokemon!B:B,Pokemon!E:E) -> Kanto
A5: Tipo: | B5: =_xlfn.XLOOKUP(B3,Pokemon!B:B,Pokemon!C:C) -> GRASS
A6: HP: | B6: =_xlfn.XLOOKUP(B3,Pokemon!B:B,Pokemon!H:H) -> 45
A7: Attack: | B7: =_xlfn.XLOOKUP(B3,Pokemon!B:B,Pokemon!I:I) -> 49
A8: Defense: | B8: =_xlfn.XLOOKUP(B3,Pokemon!B:B,Pokemon!J:J) -> 49
A9: Speed: | B9: 45
A10: Classificação: | B10: =_xlfn.XLOOKUP(B3,Pokemon!B:B,Pokemon!F:F) -> Normal

Sheet Moves
A1: Name | B1: Type | C1: Qtd(type) | D1: Cat. | E1: Power | F1: Acc. | G1: PP | H1: TM | I1: Effect | J1: Prob. (%) | K1: Classificação do Golpe
A2: Absorb | B2: GRASS | C2: =COUNTIF($B$2:$B$608,Tabela3[[#This Row],[Type]]) -> 37 | D2: Special | E2: 20 | F2: 100 | G2: 25 | I2: User recovers half the HP inflicted on opponent. | K2: =IF(E2>=100,"Muito Forte", IF(E2>=70,"Forte", "Comum")) -> Comum
A3: Acid | B3: POISON | C3: =COUNTIF($B$2:$B$608,Tabela3[[#This Row],[Type]]) -> 23 | D3: Special | E3: 40 | F3: 100 | G3: 30 | I3: May lower opponent's Special Defense. | J3: 10 | K3: =IF(E3>=100,"Muito Forte", IF(E3>=70,"Forte", "Comum")) -> Comum
A4: Acid Armor | B4: POISON | C4: =COUNTIF($B$2:$B$608,Tabela3[[#This Row],[Type]]) -> 23 | D4: Status | G4: 40 | I4: Sharply raises user's Defense. | K4: =IF(E4>=100,"Muito Forte", IF(E4>=70,"Forte", "Comum")) -> Comum
A5: Acid Spray | B5: POISON | C5: =COUNTIF($B$2:$B$608,Tabela3[[#This Row],[Type]]) -> 23 | D5: Special | E5: 40 | F5: 100 | G5: 20 | I5: Sharply lowers opponent's Special Defense. | J5: 100 | K5: =IF(E5>=100,"Muito Forte", IF(E5>=70,"Forte", "Comum")) -> Comum
A6: Acrobatics | B6: FLYING | C6: =COUNTIF($B$2:$B$608,Tabela3[[#This Row],[Type]]) -> 23 | D6: Physical | E6: 55 | F6: 100 | G6: 15 | H6: TM62 | I6: Stronger when the user does not have a held item. | K6: =IF(E6>=100,"Muito Forte", IF(E6>=70,"Forte", "Comum")) -> Comum
A7: Acupressure | B7: NORMAL | C7: =COUNTIF($B$2:$B$608,Tabela3[[#This Row],[Type]]) -> 167 | D7: Status | G7: 30 | I7: Sharply raises a random stat. | K7: =IF(E7>=100,"Muito Forte", IF(E7>=70,"Forte", "Comum")) -> Comum
A8: Aerial Ace | B8: FLYING | C8: =COUNTIF($B$2:$B$608,Tabela3[[#This Row],[Type]]) -> 23 | D8: Physical | E8: 60 | F8: ∞ | G8: 20 | H8: TM40 | I8: Ignores Accuracy and Evasiveness. | K8: =IF(E8>=100,"Muito Forte", IF(E8>=70,"Forte", "Comum")) -> Comum
A9: Aeroblast | B9: FLYING | C9: =COUNTIF($B$2:$B$608,Tabela3[[#This Row],[Type]]) -> 23 | D9: Special | E9: 100 | F9: 95 | G9: 5 | I9: High critical hit ratio. | K9: =IF(E9>=100,"Muito Forte", IF(E9>=70,"Forte", "Comum")) -> Muito Forte
A10: After You | B10: NORMAL | C10: =COUNTIF($B$2:$B$608,Tabela3[[#This Row],[Type]]) -> 167 | D10: Status | G10: 15 | I10: Gives target priority in the next turn. | K10: =IF(E10>=100,"Muito Forte", IF(E10>=70,"Forte", "Comum")) -> Comum
A11: Agility | B11: PSYCHIC | C11: =COUNTIF($B$2:$B$608,Tabela3[[#This Row],[Type]]) -> 53 | D11: Status | G11: 30 | I11: Sharply raises user's Speed. | K11: =IF(E11>=100,"Muito Forte", IF(E11>=70,"Forte", "Comum")) -> Comum
A12: Air Cutter | B12: FLYING | C12: =COUNTIF($B$2:$B$608,Tabela3[[#This Row],[Type]]) -> 23 | D12: Special | E12: 55 | F12: 95 | G12: 25 | I12: High critical hit ratio. | K12: =IF(E12>=100,"Muito Forte", IF(E12>=70,"Forte", "Comum")) -> Comum
A13: Air Slash | B13: FLYING | C13: =COUNTIF($B$2:$B$608,Tabela3[[#This Row],[Type]]) -> 23 | D13: Special | E13: 75 | F13: 95 | G13: 20 | I13: May cause flinching. | J13: 30 | K13: =IF(E13>=100,"Muito Forte", IF(E13>=70,"Forte", "Comum")) -> Forte
A14: Ally Switch | B14: PSYCHIC | C14: =COUNTIF($B$2:$B$608,Tabela3[[#This Row],[Type]]) -> 53 | D14: Status | G14: 15 | H14: TM51 | I14: User switches with opposite teammate. | K14: =IF(E14>=100,"Muito Forte", IF(E14>=70,"Forte", "Comum")) -> Comum
A15: Amnesia | B15: PSYCHIC | C15: =COUNTIF($B$2:$B$608,Tabela3[[#This Row],[Type]]) -> 53 | D15: Status | G15: 20 | I15: Sharply raises user's Special Defense. | K15: =IF(E15>=100,"Muito Forte", IF(E15>=70,"Forte", "Comum")) -> Comum
A16: AncientPower | B16: ROCK | C16: =COUNTIF($B$2:$B$608,Tabela3[[#This Row],[Type]]) -> 15 | D16: Special | E16: 60 | F16: 100 | G16: 5 | I16: May raise all user's stats at once. | J16: 10 | K16: =IF(E16>=100,"Muito Forte", IF(E16>=70,"Forte", "Comum")) -> Comum
A17: Aqua Jet | B17: WATER | C17: =COUNTIF($B$2:$B$608,Tabela3[[#This Row],[Type]]) -> 27 | D17: Physical | E17: 40 | F17: 100 | G17: 20 | I17: User attacks first. | K17: =IF(E17>=100,"Muito Forte", IF(E17>=70,"Forte", "Comum")) -> Comum
A18: Aqua Ring | B18: WATER | C18: =COUNTIF($B$2:$B$608,Tabela3[[#This Row],[Type]]) -> 27 | D18: Status | G18: 20 | I18: Restores a little HP each turn. | K18: =IF(E18>=100,"Muito Forte", IF(E18>=70,"Forte", "Comum")) -> Comum
A19: Aqua Tail | B19: WATER | C19: =COUNTIF($B$2:$B$608,Tabela3[[#This Row],[Type]]) -> 27 | D19: Physical | E19: 90 | F19: 90 | G19: 10 | K19: =IF(E19>=100,"Muito Forte", IF(E19>=70,"Forte", "Comum")) -> Forte
A20: Arm Thrust | B20: FIGHTING | C20: =COUNTIF($B$2:$B$608,Tabela3[[#This Row],[Type]]) -> 42 | D20: Physical | E20: 15 | F20: 100 | G20: 20 | I20: Hits 25 times in one turn. | K20: =IF(E20>=100,"Muito Forte", IF(E20>=70,"Forte", "Comum")) -> Comum
A21: Aromatherapy | B21: GRASS | C21: =COUNTIF($B$2:$B$608,Tabela3[[#This Row],[Type]]) -> 37 | D21: Status | G21: 5 | I21: Cures all status problems in your party. | K21: =IF(E21>=100,"Muito Forte", IF(E21>=70,"Forte", "Comum")) -> Comum
A22: Aromatic Mist | B22: FAIRY | C22: =COUNTIF($B$2:$B$608,Tabela3[[#This Row],[Type]]) -> 16 | D22: Status | F22: 100 | G22: 20 | I22: Raises Special Attack of teammates. | K22: =IF(E22>=100,"Muito Forte", IF(E22>=70,"Forte", "Comum")) -> Comum
A23: Assist | B23: NORMAL | C23: =COUNTIF($B$2:$B$608,Tabela3[[#This Row],[Type]]) -> 167 | D23: Status | G23: 20 | I23: In a Double Battle, user randomly attacks with a partner's move. | K23: =IF(E23>=100,"Muito Forte", IF(E23>=70,"Forte", "Comum")) -> Comum
A24: Assurance | B24: DARK | C24: =COUNTIF($B$2:$B$608,Tabela3[[#This Row],[Type]]) -> 31 | D24: Physical | E24: 50 | F24: 100 | G24: 10 | I24: Power doubles if opponent already took damage in the same turn. | K24: =IF(E24>=100,"Muito Forte", IF(E24>=70,"Forte", "Comum")) -> Comum
A25: Astonish | B25: GHOST | C25: =COUNTIF($B$2:$B$608,Tabela3[[#This Row],[Type]]) -> 18 | D25: Physical | E25: 30 | F25: 100 | G25: 15 | I25: May cause flinching. | J25: 30 | K25: =IF(E25>=100,"Muito Forte", IF(E25>=70,"Forte", "Comum")) -> Comum
A26: Attack Order | B26: BUG | C26: =COUNTIF($B$2:$B$608,Tabela3[[#This Row],[Type]]) -> 25 | D26: Physical | E26: 90 | F26: 100 | G26: 15 | I26: High critical hit ratio. | K26: =IF(E26>=100,"Muito Forte", IF(E26>=70,"Forte", "Comum")) -> Forte
A27: Attract | B27: NORMAL | C27: =COUNTIF($B$2:$B$608,Tabela3[[#This Row],[Type]]) -> 167 | D27: Status | F27: 100 | G27: 15 | H27: TM45 | I27: If opponent is the opposite gender, it's less likely to attack. | K27: =IF(E27>=100,"Muito Forte", IF(E27>=70,"Forte", "Comum")) -> Comum
A28: Aura Sphere | B28: FIGHTING | C28: =COUNTIF($B$2:$B$608,Tabela3[[#This Row],[Type]]) -> 42 | D28: Special | E28: 90 | F28: ∞ | G28: 20 | I28: Ignores Accuracy and Evasiveness. | K28: =IF(E28>=100,"Muito Forte", IF(E28>=70,"Forte", "Comum")) -> Forte
A29: Aurora Beam | B29: ICE | C29: =COUNTIF($B$2:$B$608,Tabela3[[#This Row],[Type]]) -> 21 | D29: Special | E29: 65 | F29: 100 | G29: 20 | I29: May lower opponent's Attack. | J29: 10 | K29: =IF(E29>=100,"Muito Forte", IF(E29>=70,"Forte", "Comum")) -> Comum
A30: Autotomize | B30: STEEL | C30: =COUNTIF($B$2:$B$608,Tabela3[[#This Row],[Type]]) -> 19 | D30: Status | G30: 15 | I30: Halves weight and sharply raises Speed. | K30: =IF(E30>=100,"Muito Forte", IF(E30>=70,"Forte", "Comum")) -> Comum
A31: Avalanche | B31: ICE | C31: =COUNTIF($B$2:$B$608,Tabela3[[#This Row],[Type]]) -> 21 | D31: Physical | E31: 60 | F31: 100 | G31: 10 | I31: Power doubles if user took damage first. | K31: =IF(E31>=100,"Muito Forte", IF(E31>=70,"Forte", "Comum")) -> Comum
A32: BabyDoll Eyes | B32: FAIRY | C32: =COUNTIF($B$2:$B$608,Tabela3[[#This Row],[Type]]) -> 16 | D32: Status | F32: 100 | G32: 30 | I32: Always goes first. Lowers the target's attack. | K32: =IF(E32>=100,"Muito Forte", IF(E32>=70,"Forte", "Comum")) -> Comum
A33: Barrage | B33: NORMAL | C33: =COUNTIF($B$2:$B$608,Tabela3[[#This Row],[Type]]) -> 167 | D33: Physical | E33: 15 | F33: 85 | G33: 20 | I33: Hits 25 times in one turn. | K33: =IF(E33>=100,"Muito Forte", IF(E33>=70,"Forte", "Comum")) -> Comum
A34: Barrier | B34: PSYCHIC | C34: =COUNTIF($B$2:$B$608,Tabela3[[#This Row],[Type]]) -> 53 | D34: Status | G34: 30 | I34: Sharply raises user's Defense. | K34: =IF(E34>=100,"Muito Forte", IF(E34>=70,"Forte", "Comum")) -> Comum
A35: Baton Pass | B35: NORMAL | C35: =COUNTIF($B$2:$B$608,Tabela3[[#This Row],[Type]]) -> 167 | D35: Status | G35: 40 | I35: User switches out and gives stat changes to the incoming Pokémon. | K35: =IF(E35>=100,"Muito Forte", IF(E35>=70,"Forte", "Comum")) -> Comum
A36: Beat Up | B36: DARK | C36: =COUNTIF($B$2:$B$608,Tabela3[[#This Row],[Type]]) -> 31 | D36: Physical | F36: 100 | G36: 30 | I36: Each Pokémon in your party attacks. | K36: =IF(E36>=100,"Muito Forte", IF(E36>=70,"Forte", "Comum")) -> Comum
A37: Belch | B37: POISON | C37: =COUNTIF($B$2:$B$608,Tabela3[[#This Row],[Type]]) -> 23 | D37: Special | E37: 120 | F37: 90 | G37: 10 | I37: Requires a held Berry to attack. | K37: =IF(E37>=100,"Muito Forte", IF(E37>=70,"Forte", "Comum")) -> Muito Forte
A38: Belly Drum | B38: NORMAL | C38: =COUNTIF($B$2:$B$608,Tabela3[[#This Row],[Type]]) -> 167 | D38: Status | G38: 10 | I38: User loses 50% of its max HP, but Attack raises to maximum. | K38: =IF(E38>=100,"Muito Forte", IF(E38>=70,"Forte", "Comum")) -> Comum
A39: Bestow | B39: NORMAL | C39: =COUNTIF($B$2:$B$608,Tabela3[[#This Row],[Type]]) -> 167 | D39: Status | G39: 15 | I39: Gives the user's held item to the target. | K39: =IF(E39>=100,"Muito Forte", IF(E39>=70,"Forte", "Comum")) -> Comum
A40: Bide | B40: NORMAL | C40: =COUNTIF($B$2:$B$608,Tabela3[[#This Row],[Type]]) -> 167 | D40: Physical | G40: 10 | I40: User takes damage for two turns then strikes back double. | K40: =IF(E40>=100,"Muito Forte", IF(E40>=70,"Forte", "Comum")) -> Comum
...

Sheet Evolution
A1: Evolving from | B1: Evolving to | C1: Level | D1: Condition | E1: Evolution Type | F1: Texto das Evoluções
A2: Bulbasaur | B2: Ivysaur | C2: 16 | E2: Level | F2: ="O Pokémon " & A2 & " evolui para " & B2 -> O Pokémon Bulbasaur evolui para Ivysaur
A3: Ivysaur | B3: Venusaur | C3: 32 | E3: Level | F3: ="O Pokémon " & A3 & " evolui para " & B3 -> O Pokémon Ivysaur evolui para Venusaur
A4: Charmander | B4: Charmeleon | C4: 16 | E4: Level | F4: ="O Pokémon " & A4 & " evolui para " & B4 -> O Pokémon Charmander evolui para Charmeleon
A5: Charmeleon | B5: Charizard | C5: 36 | E5: Level | F5: ="O Pokémon " & A5 & " evolui para " & B5 -> O Pokémon Charmeleon evolui para Charizard
A6: Squirtle | B6: Wartortle | C6: 16 | E6: Level | F6: ="O Pokémon " & A6 & " evolui para " & B6 -> O Pokémon Squirtle evolui para Wartortle
A7: Wartortle | B7: Blastoise | C7: 36 | E7: Level | F7: ="O Pokémon " & A7 & " evolui para " & B7 -> O Pokémon Wartortle evolui para Blastoise
A8: Caterpie | B8: Metapod | C8: 7 | E8: Level | F8: ="O Pokémon " & A8 & " evolui para " & B8 -> O Pokémon Caterpie evolui para Metapod
A9: Metapod | B9: Butterfree | C9: 10 | E9: Level | F9: ="O Pokémon " & A9 & " evolui para " & B9 -> O Pokémon Metapod evolui para Butterfree
A10: Weedle | B10: Kakuna | C10: 7 | E10: Level | F10: ="O Pokémon " & A10 & " evolui para " & B10 -> O Pokémon Weedle evolui para Kakuna
A11: Kakuna | B11: Beedrill | C11: 10 | E11: Level | F11: ="O Pokémon " & A11 & " evolui para " & B11 -> O Pokémon Kakuna evolui para Beedrill
A12: Pidgey | B12: Pidgeotto | C12: 18 | E12: Level | F12: ="O Pokémon " & A12 & " evolui para " & B12 -> O Pokémon Pidgey evolui para Pidgeotto
A13: Pidgeotto | B13: Pidgeot | C13: 36 | E13: Level | F13: ="O Pokémon " & A13 & " evolui para " & B13 -> O Pokémon Pidgeotto evolui para Pidgeot
... A44: Cubone | B44: Marowak | C44: 28 | E44: Level | F44: ="O Pokémon " & A44 & " evolui para " & B44 -> O Pokémon Cubone evolui para Marowak
A45: Tyrogue | B45: Hitmonlee | C45: 20 | D45: Attack > Defense | E45: Level | F45: ="O Pokémon " & A45 & " evolui para " & B45 -> O Pokémon Tyrogue evolui para Hitmonlee
A46: Tyrogue | B46: Hitmonchan | C46: 20 | D46: Attack < Defense | E46: Level | F46: ="O Pokémon " & A46 & " evolui para " & B46 -> O Pokémon Tyrogue evolui para Hitmonchan
A47: Tyrogue | B47: Hitmontop | C47: 20 | D47: Attack = Defense | E47: Level | F47: ="O Pokémon " & A47 & " evolui para " & B47 -> O Pokémon Tyrogue evolui para Hitmontop
A48: Koffing | B48: Weezing | C48: 35 | E48: Level | F48: ="O Pokémon " & A48 & " evolui para " & B48 -> O Pokémon Koffing evolui para Weezing
A49: Rhyhorn | B49: Rhydon | C49: 42 | E49: Level | F49: ="O Pokémon " & A49 & " evolui para " & B49 -> O Pokémon Rhyhorn evolui para Rhydon
A50: Horsea | B50: Seadra | C50: 32 | E50: Level | F50: ="O Pokémon " & A50 & " evolui para " & B50 -> O Pokémon Horsea evolui para Seadra
A51: Goldeen | B51: Seaking | C51: 33 | E51: Level | F51: ="O Pokémon " & A51 & " evolui para " & B51 -> O Pokémon Goldeen evolui para Seaking
A52: Smoochum | B52: Jynx | C52: 30 | E52: Level | F52: ="O Pokémon " & A52 & " evolui para " & B52 -> O Pokémon Smoochum evolui para Jynx
A53: Elekid | B53: Electabuzz | C53: 30 | E53: Level | F53: ="O Pokémon " & A53 & " evolui para " & B53 -> O Pokémon Elekid evolui para Electabuzz
A54: Magby | B54: Magmar | C54: 30 | E54: Level | F54: ="O Pokémon " & A54 & " evolui para " & B54 -> O Pokémon Magby evolui para Magmar
A55: Magikarp | B55: Gyarados | C55: 20 | E55: Level | F55: ="O Pokémon " & A55 & " evolui para " & B55 -> O Pokémon Magikarp evolui para Gyarados
A56: Omanyte | B56: Omastar | C56: 40 | E56: Level | F56: ="O Pokémon " & A56 & " evolui para " & B56 -> O Pokémon Omanyte evolui para Omastar
A57: Kabuto | B57: Kabutops | C57: 40 | E57: Level | F57: ="O Pokémon " & A57 & " evolui para " & B57 -> O Pokémon Kabuto evolui para Kabutops
A58: Dratini | B58: Dragonair | C58: 30 | E58: Level | F58: ="O Pokémon " & A58 & " evolui para " & B58 -> O Pokémon Dratini evolui para Dragonair
A59: Dragonair | B59: Dragonite | C59: 55 | E59: Level | F59: ="O Pokémon " & A59 & " evolui para " & B59 -> O Pokémon Dragonair evolui para Dragonite
... A96: Zigzagoon | B96: Linoone | C96: 20 | E96: Level | F96: ="O Pokémon " & A96 & " evolui para " & B96 -> O Pokémon Zigzagoon evolui para Linoone
A97: Wurmple | B97: Silcoon | C97: 7 | D97: Random, based on personality | E97: Level | F97: ="O Pokémon " & A97 & " evolui para " & B97 -> O Pokémon Wurmple evolui para Silcoon
A98: Silcoon | B98: Beautifly | C98: 10 | E98: Level | F98: ="O Pokémon " & A98 & " evolui para " & B98 -> O Pokémon Silcoon evolui para Beautifly
A99: Wurmple | B99: Cascoon | C99: 7 | D99: Random, based on personality | E99: Level | F99: ="O Pokémon " & A99 & " evolui para " & B99 -> O Pokémon Wurmple evolui para Cascoon
A100: Cascoon | B100: Dustox | C100: 10 | E100: Level | F100: ="O Pokémon " & A100 & " evolui para " & B100 -> O Pokémon Cascoon evolui para Dustox
A101: Lotad | B101: Lombre | C101: 14 | E101: Level | F101: ="O Pokémon " & A101 & " evolui para " & B101 -> O Pokémon Lotad evolui para Lombre
A102: Seedot | B102: Nuzleaf | C102: 14 | E102: Level | F102: ="O Pokémon " & A102 & " evolui para " & B102 -> O Pokémon Seedot evolui para Nuzleaf
A103: Taillow | B103: Swellow | C103: 22 | E103: Level | F103: ="O Pokémon " & A103 & " evolui para " & B103 -> O Pokémon Taillow evolui para Swellow
A104: Wingull | B104: Pelipper | C104: 25 | E104: Level | F104: ="O Pokémon " & A104 & " evolui para " & B104 -> O Pokémon Wingull evolui para Pelipper
A105: Ralts | B105: Kirlia | C105: 20 | E105: Level | F105: ="O Pokémon " & A105 & " evolui para " & B105 -> O Pokémon Ralts evolui para Kirlia
A106: Kirlia | B106: Gardevoir | C106: 30 | E106: Level | F106: ="O Pokémon " & A106 & " evolui para " & B106 -> O Pokémon Kirlia evolui para Gardevoir
...

Sheet TypeChart
A1: Attack | B1: Defense | C1: Effectiveness | D1: Multiplier | E1: Formalização dos Elementos
A2: NORMAL | B2: NORMAL | C2: Normal | D2: 1 | E2: ="O elemento " & Tabela2[[#This Row],[Attack]] & " é " & IF(Tabela2[[#This Row],[Multiplier]]=2,"Very Effective", IF(Tabela2[[#This Row],[Multiplier]]=0.5,"Not Very Effective", IF(Tabela2[[#This Row],[Multiplier]]=0,"No Effect", "Normal"))) & " contra o elemento " & Tabela2[[#This Row],[Defense]] -> O elemento NORMAL é Normal contra o elemento NORMAL
A3: NORMAL | B3: FIRE | C3: Normal | D3: 1 | E3: ="O elemento " & Tabela2[[#This Row],[Attack]] & " é " & IF(Tabela2[[#This Row],[Multiplier]]=2,"Very Effective", IF(Tabela2[[#This Row],[Multiplier]]=0.5,"Not Very Effective", IF(Tabela2[[#This Row],[Multiplier]]=0,"No Effect", "Normal"))) & " contra o elemento " & Tabela2[[#This Row],[Defense]] -> O elemento NORMAL é Normal contra o elemento FIRE
A4: NORMAL | B4: WATER | C4: Normal | D4: 1 | E4: ="O elemento " & Tabela2[[#This Row],[Attack]] & " é " & IF(Tabela2[[#This Row],[Multiplier]]=2,"Very Effective", IF(Tabela2[[#This Row],[Multiplier]]=0.5,"Not Very Effective", IF(Tabela2[[#This Row],[Multiplier]]=0,"No Effect", "Normal"))) & " contra o elemento " & Tabela2[[#This Row],[Defense]] -> O elemento NORMAL é Normal contra o elemento WATER
A5: NORMAL | B5: ELECTRIC | C5: Normal | D5: 1 | E5: ="O elemento " & Tabela2[[#This Row],[Attack]] & " é " & IF(Tabela2[[#This Row],[Multiplier]]=2,"Very Effective", IF(Tabela2[[#This Row],[Multiplier]]=0.5,"Not Very Effective", IF(Tabela2[[#This Row],[Multiplier]]=0,"No Effect", "Normal"))) & " contra o elemento " & Tabela2[[#This Row],[Defense]] -> O elemento NORMAL é Normal contra o elemento ELECTRIC
A6: NORMAL | B6: GRASS | C6: Normal | D6: 1 | E6: ="O elemento " & Tabela2[[#This Row],[Attack]] & " é " & IF(Tabela2[[#This Row],[Multiplier]]=2,"Very Effective", IF(Tabela2[[#This Row],[Multiplier]]=0.5,"Not Very Effective", IF(Tabela2[[#This Row],[Multiplier]]=0,"No Effect", "Normal"))) & " contra o elemento " & Tabela2[[#This Row],[Defense]] -> O elemento NORMAL é Normal contra o elemento GRASS
A7: NORMAL | B7: ICE | C7: Normal | D7: 1 | E7: ="O elemento " & Tabela2[[#This Row],[Attack]] & " é " & IF(Tabela2[[#This Row],[Multiplier]]=2,"Very Effective", IF(Tabela2[[#This Row],[Multiplier]]=0.5,"Not Very Effective", IF(Tabela2[[#This Row],[Multiplier]]=0,"No Effect", "Normal"))) & " contra o elemento " & Tabela2[[#This Row],[Defense]] -> O elemento NORMAL é Normal contra o elemento ICE
A8: NORMAL | B8: FIGHTING | C8: Normal | D8: 1 | E8: ="O elemento " & Tabela2[[#This Row],[Attack]] & " é " & IF(Tabela2[[#This Row],[Multiplier]]=2,"Very Effective", IF(Tabela2[[#This Row],[Multiplier]]=0.5,"Not Very Effective", IF(Tabela2[[#This Row],[Multiplier]]=0,"No Effect", "Normal"))) & " contra o elemento " & Tabela2[[#This Row],[Defense]] -> O elemento NORMAL é Normal contra o elemento FIGHTING
A9: NORMAL | B9: POISON | C9: Normal | D9: 1 | E9: ="O elemento " & Tabela2[[#This Row],[Attack]] & " é " & IF(Tabela2[[#This Row],[Multiplier]]=2,"Very Effective", IF(Tabela2[[#This Row],[Multiplier]]=0.5,"Not Very Effective", IF(Tabela2[[#This Row],[Multiplier]]=0,"No Effect", "Normal"))) & " contra o elemento " & Tabela2[[#This Row],[Defense]] -> O elemento NORMAL é Normal contra o elemento POISON
A10: NORMAL | B10: GROUND | C10: Normal | D10: 1 | E10: ="O elemento " & Tabela2[[#This Row],[Attack]] & " é " & IF(Tabela2[[#This Row],[Multiplier]]=2,"Very Effective", IF(Tabela2[[#This Row],[Multiplier]]=0.5,"Not Very Effective", IF(Tabela2[[#This Row],[Multiplier]]=0,"No Effect", "Normal"))) & " contra o elemento " & Tabela2[[#This Row],[Defense]] -> O elemento NORMAL é Normal contra o elemento GROUND
A11: NORMAL | B11: FLYING | C11: Normal | D11: 1 | E11: ="O elemento " & Tabela2[[#This Row],[Attack]] & " é " & IF(Tabela2[[#This Row],[Multiplier]]=2,"Very Effective", IF(Tabela2[[#This Row],[Multiplier]]=0.5,"Not Very Effective", IF(Tabela2[[#This Row],[Multiplier]]=0,"No Effect", "Normal"))) & " contra o elemento " & Tabela2[[#This Row],[Defense]] -> O elemento NORMAL é Normal contra o elemento FLYING
A12: NORMAL | B12: PSYCHIC | C12: Normal | D12: 1 | E12: ="O elemento " & Tabela2[[#This Row],[Attack]] & " é " & IF(Tabela2[[#This Row],[Multiplier]]=2,"Very Effective", IF(Tabela2[[#This Row],[Multiplier]]=0.5,"Not Very Effective", IF(Tabela2[[#This Row],[Multiplier]]=0,"No Effect", "Normal"))) & " contra o elemento " & Tabela2[[#This Row],[Defense]] -> O elemento NORMAL é Normal contra o elemento PSYCHIC
A13: NORMAL | B13: BUG | C13: Normal | D13: 1 | E13: ="O elemento " & Tabela2[[#This Row],[Attack]] & " é " & IF(Tabela2[[#This Row],[Multiplier]]=2,"Very Effective", IF(Tabela2[[#This Row],[Multiplier]]=0.5,"Not Very Effective", IF(Tabela2[[#This Row],[Multiplier]]=0,"No Effect", "Normal"))) & " contra o elemento " & Tabela2[[#This Row],[Defense]] -> O elemento NORMAL é Normal contra o elemento BUG
... A325: FAIRY | B325: FAIRY | C325: Normal | D325: 1 | E325: ="O elemento " & Tabela2[[#This Row],[Attack]] & " é " & IF(Tabela2[[#This Row],[Multiplier]]=2,"Very Effective", IF(Tabela2[[#This Row],[Multiplier]]=0.5,"Not Very Effective", IF(Tabela2[[#This Row],[Multiplier]]=0,"No Effect", "Normal"))) & " contra o elemento " & Tabela2[[#This Row],[Defense]] -> O elemento FAIRY é Normal contra o elemento FAIRY
